[2024-09-22T11:42:33.487+0000] {local_task_job_runner.py:120} INFO - ::group::Pre task execution logs
[2024-09-22T11:42:33.616+0000] {taskinstance.py:2076} INFO - Dependencies all met for dep_context=non-requeueable deps ti=<TaskInstance: example_passing_params_via_test_command.also_run_this scheduled__2024-09-22T11:40:00+00:00 [queued]>
[2024-09-22T11:42:33.637+0000] {taskinstance.py:2076} INFO - Dependencies all met for dep_context=requeueable deps ti=<TaskInstance: example_passing_params_via_test_command.also_run_this scheduled__2024-09-22T11:40:00+00:00 [queued]>
[2024-09-22T11:42:33.639+0000] {taskinstance.py:2306} INFO - Starting attempt 1 of 1
[2024-09-22T11:42:34.020+0000] {taskinstance.py:2330} INFO - Executing <Task(BashOperator): also_run_this> on 2024-09-22 11:40:00+00:00
[2024-09-22T11:42:34.062+0000] {warnings.py:112} WARNING - /home/***/.local/lib/python3.12/site-packages/***/task/task_runner/standard_task_runner.py:62: DeprecationWarning: This process (pid=1651) is multi-threaded, use of fork() may lead to deadlocks in the child.
  pid = os.fork()

[2024-09-22T11:42:34.068+0000] {standard_task_runner.py:64} INFO - Started process 1669 to run task
[2024-09-22T11:42:34.067+0000] {standard_task_runner.py:90} INFO - Running: ['***', 'tasks', 'run', 'example_passing_params_via_test_command', 'also_run_this', 'scheduled__2024-09-22T11:40:00+00:00', '--job-id', '2767', '--raw', '--subdir', '/home/***/.local/lib/python3.12/site-packages/***/example_dags/example_passing_params_via_test_command.py', '--cfg-path', '/tmp/tmpno0ns1n9']
[2024-09-22T11:42:34.083+0000] {standard_task_runner.py:91} INFO - Job 2767: Subtask also_run_this
[2024-09-22T11:42:34.636+0000] {task_command.py:426} INFO - Running <TaskInstance: example_passing_params_via_test_command.also_run_this scheduled__2024-09-22T11:40:00+00:00 [running]> on host 1d2bd9c1668e
[2024-09-22T11:42:35.260+0000] {abstractoperator.py:725} ERROR - Exception rendering Jinja template for task 'also_run_this', field 'env'. Template: {'FOO': '{{ params.foo }}', 'MIFF': '{{ params.miff }}'}
Traceback (most recent call last):
  File "/home/airflow/.local/lib/python3.12/site-packages/airflow/models/abstractoperator.py", line 717, in _do_render_template_fields
    rendered_content = self.render_template(
                       ^^^^^^^^^^^^^^^^^^^^^
  File "/home/airflow/.local/lib/python3.12/site-packages/airflow/template/templater.py", line 181, in render_template
    return {k: self.render_template(v, context, jinja_env, oids) for k, v in value.items()}
               ^^^^^^^^^^^^^^^^^^^^^^^^^^^^^^^^^^^^^^^^^^^^^^^^^
  File "/home/airflow/.local/lib/python3.12/site-packages/airflow/template/templater.py", line 169, in render_template
    return self._render(template, context)
           ^^^^^^^^^^^^^^^^^^^^^^^^^^^^^^^
  File "/home/airflow/.local/lib/python3.12/site-packages/airflow/models/abstractoperator.py", line 675, in _render
    return super()._render(template, context, dag=dag)
           ^^^^^^^^^^^^^^^^^^^^^^^^^^^^^^^^^^^^^^^^^^^
  File "/home/airflow/.local/lib/python3.12/site-packages/airflow/template/templater.py", line 126, in _render
    return render_template_to_string(template, context)
           ^^^^^^^^^^^^^^^^^^^^^^^^^^^^^^^^^^^^^^^^^^^^
  File "/home/airflow/.local/lib/python3.12/site-packages/airflow/utils/helpers.py", line 289, in render_template_to_string
    return render_template(template, cast(MutableMapping[str, Any], context), native=False)
           ^^^^^^^^^^^^^^^^^^^^^^^^^^^^^^^^^^^^^^^^^^^^^^^^^^^^^^^^^^^^^^^^^^^^^^^^^^^^^^^^
  File "/home/airflow/.local/lib/python3.12/site-packages/airflow/utils/helpers.py", line 284, in render_template
    return "".join(nodes)
           ^^^^^^^^^^^^^^
  File "<template>", line 12, in root
  File "/home/airflow/.local/lib/python3.12/site-packages/jinja2/runtime.py", line 857, in _fail_with_undefined_error
    raise self._undefined_exception(self._undefined_message)
jinja2.exceptions.UndefinedError: 'dict object' has no attribute 'foo'
[2024-09-22T11:42:36.443+0000] {taskinstance.py:2905} ERROR - Task failed with exception
Traceback (most recent call last):
  File "/home/airflow/.local/lib/python3.12/site-packages/airflow/models/taskinstance.py", line 2479, in _run_raw_task
    self._execute_task_with_callbacks(context, test_mode, session=session)
  File "/home/airflow/.local/lib/python3.12/site-packages/airflow/models/taskinstance.py", line 2633, in _execute_task_with_callbacks
    task_orig = self.render_templates(context=context, jinja_env=jinja_env)
                ^^^^^^^^^^^^^^^^^^^^^^^^^^^^^^^^^^^^^^^^^^^^^^^^^^^^^^^^^^^
  File "/home/airflow/.local/lib/python3.12/site-packages/airflow/models/taskinstance.py", line 3094, in render_templates
    original_task.render_template_fields(context, jinja_env)
  File "/home/airflow/.local/lib/python3.12/site-packages/airflow/models/baseoperator.py", line 1337, in render_template_fields
    self._do_render_template_fields(self, self.template_fields, context, jinja_env, set())
  File "/home/airflow/.local/lib/python3.12/site-packages/airflow/models/abstractoperator.py", line 717, in _do_render_template_fields
    rendered_content = self.render_template(
                       ^^^^^^^^^^^^^^^^^^^^^
  File "/home/airflow/.local/lib/python3.12/site-packages/airflow/template/templater.py", line 181, in render_template
    return {k: self.render_template(v, context, jinja_env, oids) for k, v in value.items()}
               ^^^^^^^^^^^^^^^^^^^^^^^^^^^^^^^^^^^^^^^^^^^^^^^^^
  File "/home/airflow/.local/lib/python3.12/site-packages/airflow/template/templater.py", line 169, in render_template
    return self._render(template, context)
           ^^^^^^^^^^^^^^^^^^^^^^^^^^^^^^^
  File "/home/airflow/.local/lib/python3.12/site-packages/airflow/models/abstractoperator.py", line 675, in _render
    return super()._render(template, context, dag=dag)
           ^^^^^^^^^^^^^^^^^^^^^^^^^^^^^^^^^^^^^^^^^^^
  File "/home/airflow/.local/lib/python3.12/site-packages/airflow/template/templater.py", line 126, in _render
    return render_template_to_string(template, context)
           ^^^^^^^^^^^^^^^^^^^^^^^^^^^^^^^^^^^^^^^^^^^^
  File "/home/airflow/.local/lib/python3.12/site-packages/airflow/utils/helpers.py", line 289, in render_template_to_string
    return render_template(template, cast(MutableMapping[str, Any], context), native=False)
           ^^^^^^^^^^^^^^^^^^^^^^^^^^^^^^^^^^^^^^^^^^^^^^^^^^^^^^^^^^^^^^^^^^^^^^^^^^^^^^^^
  File "/home/airflow/.local/lib/python3.12/site-packages/airflow/utils/helpers.py", line 284, in render_template
    return "".join(nodes)
           ^^^^^^^^^^^^^^
  File "<template>", line 12, in root
  File "/home/airflow/.local/lib/python3.12/site-packages/jinja2/runtime.py", line 857, in _fail_with_undefined_error
    raise self._undefined_exception(self._undefined_message)
jinja2.exceptions.UndefinedError: 'dict object' has no attribute 'foo'
[2024-09-22T11:42:36.879+0000] {taskinstance.py:1206} INFO - Marking task as FAILED. dag_id=example_passing_params_via_test_command, task_id=also_run_this, run_id=scheduled__2024-09-22T11:40:00+00:00, execution_date=20240922T114000, start_date=20240922T114233, end_date=20240922T114236
[2024-09-22T11:42:38.590+0000] {standard_task_runner.py:110} ERROR - Failed to execute job 2767 for task also_run_this ('dict object' has no attribute 'foo'; 1669)
[2024-09-22T11:42:38.760+0000] {local_task_job_runner.py:243} INFO - Task exited with return code 1
[2024-09-22T11:42:38.906+0000] {taskinstance.py:3503} INFO - 0 downstream tasks scheduled from follow-on schedule check
[2024-09-22T11:42:39.923+0000] {local_task_job_runner.py:222} INFO - ::endgroup::
