[2024-09-22T11:43:39.613+0000] {local_task_job_runner.py:120} INFO - ::group::Pre task execution logs
[2024-09-22T11:43:39.832+0000] {taskinstance.py:2076} INFO - Dependencies all met for dep_context=non-requeueable deps ti=<TaskInstance: example_passing_params_via_test_command.also_run_this scheduled__2024-09-22T11:42:00+00:00 [queued]>
[2024-09-22T11:43:39.900+0000] {taskinstance.py:2076} INFO - Dependencies all met for dep_context=requeueable deps ti=<TaskInstance: example_passing_params_via_test_command.also_run_this scheduled__2024-09-22T11:42:00+00:00 [queued]>
[2024-09-22T11:43:39.900+0000] {taskinstance.py:2306} INFO - Starting attempt 1 of 1
[2024-09-22T11:43:40.187+0000] {taskinstance.py:2330} INFO - Executing <Task(BashOperator): also_run_this> on 2024-09-22 11:42:00+00:00
[2024-09-22T11:43:40.400+0000] {warnings.py:112} WARNING - /home/***/.local/lib/python3.12/site-packages/***/task/task_runner/standard_task_runner.py:62: DeprecationWarning: This process (pid=1800) is multi-threaded, use of fork() may lead to deadlocks in the child.
  pid = os.fork()

[2024-09-22T11:43:40.417+0000] {standard_task_runner.py:64} INFO - Started process 1817 to run task
[2024-09-22T11:43:40.400+0000] {standard_task_runner.py:90} INFO - Running: ['***', 'tasks', 'run', 'example_passing_params_via_test_command', 'also_run_this', 'scheduled__2024-09-22T11:42:00+00:00', '--job-id', '2811', '--raw', '--subdir', '/home/***/.local/lib/python3.12/site-packages/***/example_dags/example_passing_params_via_test_command.py', '--cfg-path', '/tmp/tmp8710wlrv']
[2024-09-22T11:43:40.423+0000] {standard_task_runner.py:91} INFO - Job 2811: Subtask also_run_this
[2024-09-22T11:43:41.737+0000] {task_command.py:426} INFO - Running <TaskInstance: example_passing_params_via_test_command.also_run_this scheduled__2024-09-22T11:42:00+00:00 [running]> on host 1d2bd9c1668e
[2024-09-22T11:43:42.764+0000] {abstractoperator.py:725} ERROR - Exception rendering Jinja template for task 'also_run_this', field 'env'. Template: {'FOO': '{{ params.foo }}', 'MIFF': '{{ params.miff }}'}
Traceback (most recent call last):
  File "/home/airflow/.local/lib/python3.12/site-packages/airflow/models/abstractoperator.py", line 717, in _do_render_template_fields
    rendered_content = self.render_template(
                       ^^^^^^^^^^^^^^^^^^^^^
  File "/home/airflow/.local/lib/python3.12/site-packages/airflow/template/templater.py", line 181, in render_template
    return {k: self.render_template(v, context, jinja_env, oids) for k, v in value.items()}
               ^^^^^^^^^^^^^^^^^^^^^^^^^^^^^^^^^^^^^^^^^^^^^^^^^
  File "/home/airflow/.local/lib/python3.12/site-packages/airflow/template/templater.py", line 169, in render_template
    return self._render(template, context)
           ^^^^^^^^^^^^^^^^^^^^^^^^^^^^^^^
  File "/home/airflow/.local/lib/python3.12/site-packages/airflow/models/abstractoperator.py", line 675, in _render
    return super()._render(template, context, dag=dag)
           ^^^^^^^^^^^^^^^^^^^^^^^^^^^^^^^^^^^^^^^^^^^
  File "/home/airflow/.local/lib/python3.12/site-packages/airflow/template/templater.py", line 126, in _render
    return render_template_to_string(template, context)
           ^^^^^^^^^^^^^^^^^^^^^^^^^^^^^^^^^^^^^^^^^^^^
  File "/home/airflow/.local/lib/python3.12/site-packages/airflow/utils/helpers.py", line 289, in render_template_to_string
    return render_template(template, cast(MutableMapping[str, Any], context), native=False)
           ^^^^^^^^^^^^^^^^^^^^^^^^^^^^^^^^^^^^^^^^^^^^^^^^^^^^^^^^^^^^^^^^^^^^^^^^^^^^^^^^
  File "/home/airflow/.local/lib/python3.12/site-packages/airflow/utils/helpers.py", line 284, in render_template
    return "".join(nodes)
           ^^^^^^^^^^^^^^
  File "<template>", line 12, in root
  File "/home/airflow/.local/lib/python3.12/site-packages/jinja2/runtime.py", line 857, in _fail_with_undefined_error
    raise self._undefined_exception(self._undefined_message)
jinja2.exceptions.UndefinedError: 'dict object' has no attribute 'foo'
[2024-09-22T11:43:42.776+0000] {taskinstance.py:2905} ERROR - Task failed with exception
Traceback (most recent call last):
  File "/home/airflow/.local/lib/python3.12/site-packages/airflow/models/taskinstance.py", line 2479, in _run_raw_task
    self._execute_task_with_callbacks(context, test_mode, session=session)
  File "/home/airflow/.local/lib/python3.12/site-packages/airflow/models/taskinstance.py", line 2633, in _execute_task_with_callbacks
    task_orig = self.render_templates(context=context, jinja_env=jinja_env)
                ^^^^^^^^^^^^^^^^^^^^^^^^^^^^^^^^^^^^^^^^^^^^^^^^^^^^^^^^^^^
  File "/home/airflow/.local/lib/python3.12/site-packages/airflow/models/taskinstance.py", line 3094, in render_templates
    original_task.render_template_fields(context, jinja_env)
  File "/home/airflow/.local/lib/python3.12/site-packages/airflow/models/baseoperator.py", line 1337, in render_template_fields
    self._do_render_template_fields(self, self.template_fields, context, jinja_env, set())
  File "/home/airflow/.local/lib/python3.12/site-packages/airflow/models/abstractoperator.py", line 717, in _do_render_template_fields
    rendered_content = self.render_template(
                       ^^^^^^^^^^^^^^^^^^^^^
  File "/home/airflow/.local/lib/python3.12/site-packages/airflow/template/templater.py", line 181, in render_template
    return {k: self.render_template(v, context, jinja_env, oids) for k, v in value.items()}
               ^^^^^^^^^^^^^^^^^^^^^^^^^^^^^^^^^^^^^^^^^^^^^^^^^
  File "/home/airflow/.local/lib/python3.12/site-packages/airflow/template/templater.py", line 169, in render_template
    return self._render(template, context)
           ^^^^^^^^^^^^^^^^^^^^^^^^^^^^^^^
  File "/home/airflow/.local/lib/python3.12/site-packages/airflow/models/abstractoperator.py", line 675, in _render
    return super()._render(template, context, dag=dag)
           ^^^^^^^^^^^^^^^^^^^^^^^^^^^^^^^^^^^^^^^^^^^
  File "/home/airflow/.local/lib/python3.12/site-packages/airflow/template/templater.py", line 126, in _render
    return render_template_to_string(template, context)
           ^^^^^^^^^^^^^^^^^^^^^^^^^^^^^^^^^^^^^^^^^^^^
  File "/home/airflow/.local/lib/python3.12/site-packages/airflow/utils/helpers.py", line 289, in render_template_to_string
    return render_template(template, cast(MutableMapping[str, Any], context), native=False)
           ^^^^^^^^^^^^^^^^^^^^^^^^^^^^^^^^^^^^^^^^^^^^^^^^^^^^^^^^^^^^^^^^^^^^^^^^^^^^^^^^
  File "/home/airflow/.local/lib/python3.12/site-packages/airflow/utils/helpers.py", line 284, in render_template
    return "".join(nodes)
           ^^^^^^^^^^^^^^
  File "<template>", line 12, in root
  File "/home/airflow/.local/lib/python3.12/site-packages/jinja2/runtime.py", line 857, in _fail_with_undefined_error
    raise self._undefined_exception(self._undefined_message)
jinja2.exceptions.UndefinedError: 'dict object' has no attribute 'foo'
[2024-09-22T11:43:42.805+0000] {taskinstance.py:1206} INFO - Marking task as FAILED. dag_id=example_passing_params_via_test_command, task_id=also_run_this, run_id=scheduled__2024-09-22T11:42:00+00:00, execution_date=20240922T114200, start_date=20240922T114339, end_date=20240922T114342
[2024-09-22T11:43:43.195+0000] {standard_task_runner.py:110} ERROR - Failed to execute job 2811 for task also_run_this ('dict object' has no attribute 'foo'; 1817)
[2024-09-22T11:43:43.297+0000] {local_task_job_runner.py:243} INFO - Task exited with return code 1
[2024-09-22T11:43:43.391+0000] {taskinstance.py:3503} INFO - 0 downstream tasks scheduled from follow-on schedule check
[2024-09-22T11:43:43.762+0000] {local_task_job_runner.py:222} INFO - ::endgroup::
