[2024-09-25T09:09:58.857+0000] {local_task_job_runner.py:123} INFO - ::group::Pre task execution logs
[2024-09-25T09:09:58.883+0000] {taskinstance.py:2612} INFO - Dependencies all met for dep_context=non-requeueable deps ti=<TaskInstance: NY_TAXI.download_data scheduled__2021-05-01T00:00:00+00:00 [queued]>
[2024-09-25T09:09:58.896+0000] {taskinstance.py:2612} INFO - Dependencies all met for dep_context=requeueable deps ti=<TaskInstance: NY_TAXI.download_data scheduled__2021-05-01T00:00:00+00:00 [queued]>
[2024-09-25T09:09:58.897+0000] {taskinstance.py:2865} INFO - Starting attempt 13 of 13
[2024-09-25T09:09:58.932+0000] {taskinstance.py:2888} INFO - Executing <Task(BashOperator): download_data> on 2021-05-01 00:00:00+00:00
[2024-09-25T09:09:58.949+0000] {standard_task_runner.py:104} INFO - Running: ['***', 'tasks', 'run', 'NY_TAXI', 'download_data', 'scheduled__2021-05-01T00:00:00+00:00', '--job-id', '458', '--raw', '--subdir', 'DAGS_FOLDER/download.py', '--cfg-path', '/tmp/tmpae3gcjuf']
[2024-09-25T09:09:58.953+0000] {standard_task_runner.py:105} INFO - Job 458: Subtask download_data
[2024-09-25T09:09:58.955+0000] {logging_mixin.py:190} WARNING - /home/***/.local/lib/python3.12/site-packages/***/task/task_runner/standard_task_runner.py:70 DeprecationWarning: This process (pid=583) is multi-threaded, use of fork() may lead to deadlocks in the child.
[2024-09-25T09:09:58.956+0000] {standard_task_runner.py:72} INFO - Started process 585 to run task
[2024-09-25T09:09:59.032+0000] {task_command.py:467} INFO - Running <TaskInstance: NY_TAXI.download_data scheduled__2021-05-01T00:00:00+00:00 [running]> on host e7ca35b1115e
[2024-09-25T09:10:00.531+0000] {taskinstance.py:3131} INFO - Exporting env vars: AIRFLOW_CTX_DAG_OWNER='***' AIRFLOW_CTX_DAG_ID='NY_TAXI' AIRFLOW_CTX_TASK_ID='download_data' AIRFLOW_CTX_EXECUTION_DATE='2021-05-01T00:00:00+00:00' AIRFLOW_CTX_TRY_NUMBER='13' AIRFLOW_CTX_DAG_RUN_ID='scheduled__2021-05-01T00:00:00+00:00'
[2024-09-25T09:10:00.533+0000] {taskinstance.py:731} INFO - ::endgroup::
[2024-09-25T09:10:00.572+0000] {subprocess.py:63} INFO - Tmp dir root location: /tmp
[2024-09-25T09:10:00.574+0000] {subprocess.py:75} INFO - Running command: ['/usr/bin/bash', '-c', 'curl -sSL https://github.com/DataTalksClub/nyc-tlc-data/releases/download/yellow/yellow_tripdata_2021-05.csv.gz > /opt/***/output_2021-05.csv.gz']
[2024-09-25T09:10:00.632+0000] {subprocess.py:86} INFO - Output:
[2024-09-25T09:11:16.224+0000] {subprocess.py:93} INFO - curl: (56) Recv failure: Connection reset by peer
[2024-09-25T09:11:16.234+0000] {subprocess.py:97} INFO - Command exited with return code 56
[2024-09-25T09:11:16.249+0000] {taskinstance.py:3310} ERROR - Task failed with exception
Traceback (most recent call last):
  File "/home/airflow/.local/lib/python3.12/site-packages/airflow/models/taskinstance.py", line 767, in _execute_task
    result = _execute_callable(context=context, **execute_callable_kwargs)
             ^^^^^^^^^^^^^^^^^^^^^^^^^^^^^^^^^^^^^^^^^^^^^^^^^^^^^^^^^^^^^
  File "/home/airflow/.local/lib/python3.12/site-packages/airflow/models/taskinstance.py", line 733, in _execute_callable
    return ExecutionCallableRunner(
           ^^^^^^^^^^^^^^^^^^^^^^^^
  File "/home/airflow/.local/lib/python3.12/site-packages/airflow/utils/operator_helpers.py", line 252, in run
    return self.func(*args, **kwargs)
           ^^^^^^^^^^^^^^^^^^^^^^^^^^
  File "/home/airflow/.local/lib/python3.12/site-packages/airflow/models/baseoperator.py", line 406, in wrapper
    return func(self, *args, **kwargs)
           ^^^^^^^^^^^^^^^^^^^^^^^^^^^
  File "/home/airflow/.local/lib/python3.12/site-packages/airflow/operators/bash.py", line 249, in execute
    raise AirflowException(
airflow.exceptions.AirflowException: Bash command failed. The command returned a non-zero exit code 56.
[2024-09-25T09:11:16.303+0000] {taskinstance.py:1225} INFO - Marking task as FAILED. dag_id=NY_TAXI, task_id=download_data, run_id=scheduled__2021-05-01T00:00:00+00:00, execution_date=20210501T000000, start_date=20240925T090958, end_date=20240925T091116
[2024-09-25T09:11:16.458+0000] {taskinstance.py:340} INFO - ::group::Post task execution logs
[2024-09-25T09:11:16.459+0000] {standard_task_runner.py:124} ERROR - Failed to execute job 458 for task download_data (Bash command failed. The command returned a non-zero exit code 56.; 585)
Traceback (most recent call last):
  File "/home/airflow/.local/lib/python3.12/site-packages/airflow/task/task_runner/standard_task_runner.py", line 117, in _start_by_fork
    ret = args.func(args, dag=self.dag)
          ^^^^^^^^^^^^^^^^^^^^^^^^^^^^^
  File "/home/airflow/.local/lib/python3.12/site-packages/airflow/cli/cli_config.py", line 49, in command
    return func(*args, **kwargs)
           ^^^^^^^^^^^^^^^^^^^^^
  File "/home/airflow/.local/lib/python3.12/site-packages/airflow/utils/cli.py", line 115, in wrapper
    return f(*args, **kwargs)
           ^^^^^^^^^^^^^^^^^^
  File "/home/airflow/.local/lib/python3.12/site-packages/airflow/cli/commands/task_command.py", line 483, in task_run
    task_return_code = _run_task_by_selected_method(args, _dag, ti)
                       ^^^^^^^^^^^^^^^^^^^^^^^^^^^^^^^^^^^^^^^^^^^^
  File "/home/airflow/.local/lib/python3.12/site-packages/airflow/cli/commands/task_command.py", line 256, in _run_task_by_selected_method
    return _run_raw_task(args, ti)
           ^^^^^^^^^^^^^^^^^^^^^^^
  File "/home/airflow/.local/lib/python3.12/site-packages/airflow/cli/commands/task_command.py", line 341, in _run_raw_task
    return ti._run_raw_task(
           ^^^^^^^^^^^^^^^^^
  File "/home/airflow/.local/lib/python3.12/site-packages/airflow/utils/session.py", line 97, in wrapper
    return func(*args, session=session, **kwargs)
           ^^^^^^^^^^^^^^^^^^^^^^^^^^^^^^^^^^^^^^
  File "/home/airflow/.local/lib/python3.12/site-packages/airflow/models/taskinstance.py", line 3004, in _run_raw_task
    return _run_raw_task(
           ^^^^^^^^^^^^^^
  File "/home/airflow/.local/lib/python3.12/site-packages/airflow/models/taskinstance.py", line 273, in _run_raw_task
    TaskInstance._execute_task_with_callbacks(
  File "/home/airflow/.local/lib/python3.12/site-packages/airflow/models/taskinstance.py", line 3158, in _execute_task_with_callbacks
    result = self._execute_task(context, task_orig)
             ^^^^^^^^^^^^^^^^^^^^^^^^^^^^^^^^^^^^^^
  File "/home/airflow/.local/lib/python3.12/site-packages/airflow/models/taskinstance.py", line 3182, in _execute_task
    return _execute_task(self, context, task_orig)
           ^^^^^^^^^^^^^^^^^^^^^^^^^^^^^^^^^^^^^^^
  File "/home/airflow/.local/lib/python3.12/site-packages/airflow/models/taskinstance.py", line 767, in _execute_task
    result = _execute_callable(context=context, **execute_callable_kwargs)
             ^^^^^^^^^^^^^^^^^^^^^^^^^^^^^^^^^^^^^^^^^^^^^^^^^^^^^^^^^^^^^
  File "/home/airflow/.local/lib/python3.12/site-packages/airflow/models/taskinstance.py", line 733, in _execute_callable
    return ExecutionCallableRunner(
           ^^^^^^^^^^^^^^^^^^^^^^^^
  File "/home/airflow/.local/lib/python3.12/site-packages/airflow/utils/operator_helpers.py", line 252, in run
    return self.func(*args, **kwargs)
           ^^^^^^^^^^^^^^^^^^^^^^^^^^
  File "/home/airflow/.local/lib/python3.12/site-packages/airflow/models/baseoperator.py", line 406, in wrapper
    return func(self, *args, **kwargs)
           ^^^^^^^^^^^^^^^^^^^^^^^^^^^
  File "/home/airflow/.local/lib/python3.12/site-packages/airflow/operators/bash.py", line 249, in execute
    raise AirflowException(
airflow.exceptions.AirflowException: Bash command failed. The command returned a non-zero exit code 56.
[2024-09-25T09:11:16.520+0000] {local_task_job_runner.py:266} INFO - Task exited with return code 1
[2024-09-25T09:11:16.550+0000] {taskinstance.py:3900} INFO - 0 downstream tasks scheduled from follow-on schedule check
[2024-09-25T09:11:16.584+0000] {local_task_job_runner.py:245} INFO - ::endgroup::
