[2024-09-23T08:33:37.516+0000] {local_task_job_runner.py:123} INFO - ::group::Pre task execution logs
[2024-09-23T08:33:37.541+0000] {taskinstance.py:2612} INFO - Dependencies all met for dep_context=non-requeueable deps ti=<TaskInstance: NY_TAXI.download_data scheduled__2021-05-01T00:00:00+00:00 [queued]>
[2024-09-23T08:33:37.553+0000] {taskinstance.py:2612} INFO - Dependencies all met for dep_context=requeueable deps ti=<TaskInstance: NY_TAXI.download_data scheduled__2021-05-01T00:00:00+00:00 [queued]>
[2024-09-23T08:33:37.554+0000] {taskinstance.py:2865} INFO - Starting attempt 3 of 3
[2024-09-23T08:33:37.588+0000] {taskinstance.py:2888} INFO - Executing <Task(BashOperator): download_data> on 2021-05-01 00:00:00+00:00
[2024-09-23T08:33:37.602+0000] {standard_task_runner.py:104} INFO - Running: ['***', 'tasks', 'run', 'NY_TAXI', 'download_data', 'scheduled__2021-05-01T00:00:00+00:00', '--job-id', '433', '--raw', '--subdir', 'DAGS_FOLDER/download.py', '--cfg-path', '/tmp/tmpt7h2i8c3']
[2024-09-23T08:33:37.605+0000] {standard_task_runner.py:105} INFO - Job 433: Subtask download_data
[2024-09-23T08:33:37.608+0000] {logging_mixin.py:190} WARNING - /home/***/.local/lib/python3.12/site-packages/***/task/task_runner/standard_task_runner.py:70 DeprecationWarning: This process (pid=802) is multi-threaded, use of fork() may lead to deadlocks in the child.
[2024-09-23T08:33:37.609+0000] {standard_task_runner.py:72} INFO - Started process 803 to run task
[2024-09-23T08:33:37.688+0000] {task_command.py:467} INFO - Running <TaskInstance: NY_TAXI.download_data scheduled__2021-05-01T00:00:00+00:00 [running]> on host c6317fbbba71
[2024-09-23T08:33:37.982+0000] {taskinstance.py:3131} INFO - Exporting env vars: AIRFLOW_CTX_DAG_OWNER='***' AIRFLOW_CTX_DAG_ID='NY_TAXI' AIRFLOW_CTX_TASK_ID='download_data' AIRFLOW_CTX_EXECUTION_DATE='2021-05-01T00:00:00+00:00' AIRFLOW_CTX_TRY_NUMBER='3' AIRFLOW_CTX_DAG_RUN_ID='scheduled__2021-05-01T00:00:00+00:00'
[2024-09-23T08:33:37.982+0000] {taskinstance.py:731} INFO - ::endgroup::
[2024-09-23T08:33:38.008+0000] {subprocess.py:63} INFO - Tmp dir root location: /tmp
[2024-09-23T08:33:38.009+0000] {subprocess.py:75} INFO - Running command: ['/usr/bin/bash', '-c', 'curl -sSL  https://github.com/DataTalksClub/nyc-tlc-data/releases/tag/yellow/yellow_tripdata_2021-05.csv.gz > /opt/***/output_2021-05']
[2024-09-23T08:33:38.030+0000] {subprocess.py:86} INFO - Output:
[2024-09-23T08:38:39.007+0000] {subprocess.py:93} INFO - curl: (28) SSL connection timeout
[2024-09-23T08:38:39.011+0000] {subprocess.py:97} INFO - Command exited with return code 28
[2024-09-23T08:38:39.557+0000] {taskinstance.py:3310} ERROR - Task failed with exception
Traceback (most recent call last):
  File "/home/airflow/.local/lib/python3.12/site-packages/airflow/models/taskinstance.py", line 767, in _execute_task
    result = _execute_callable(context=context, **execute_callable_kwargs)
             ^^^^^^^^^^^^^^^^^^^^^^^^^^^^^^^^^^^^^^^^^^^^^^^^^^^^^^^^^^^^^
  File "/home/airflow/.local/lib/python3.12/site-packages/airflow/models/taskinstance.py", line 733, in _execute_callable
    return ExecutionCallableRunner(
           ^^^^^^^^^^^^^^^^^^^^^^^^
  File "/home/airflow/.local/lib/python3.12/site-packages/airflow/utils/operator_helpers.py", line 252, in run
    return self.func(*args, **kwargs)
           ^^^^^^^^^^^^^^^^^^^^^^^^^^
  File "/home/airflow/.local/lib/python3.12/site-packages/airflow/models/baseoperator.py", line 406, in wrapper
    return func(self, *args, **kwargs)
           ^^^^^^^^^^^^^^^^^^^^^^^^^^^
  File "/home/airflow/.local/lib/python3.12/site-packages/airflow/operators/bash.py", line 249, in execute
    raise AirflowException(
airflow.exceptions.AirflowException: Bash command failed. The command returned a non-zero exit code 28.
[2024-09-23T08:38:39.784+0000] {taskinstance.py:1225} INFO - Marking task as FAILED. dag_id=NY_TAXI, task_id=download_data, run_id=scheduled__2021-05-01T00:00:00+00:00, execution_date=20210501T000000, start_date=20240923T083337, end_date=20240923T083839
[2024-09-23T08:38:39.905+0000] {taskinstance.py:340} INFO - ::group::Post task execution logs
[2024-09-23T08:38:39.907+0000] {standard_task_runner.py:124} ERROR - Failed to execute job 433 for task download_data (Bash command failed. The command returned a non-zero exit code 28.; 803)
Traceback (most recent call last):
  File "/home/airflow/.local/lib/python3.12/site-packages/airflow/task/task_runner/standard_task_runner.py", line 117, in _start_by_fork
    ret = args.func(args, dag=self.dag)
          ^^^^^^^^^^^^^^^^^^^^^^^^^^^^^
  File "/home/airflow/.local/lib/python3.12/site-packages/airflow/cli/cli_config.py", line 49, in command
    return func(*args, **kwargs)
           ^^^^^^^^^^^^^^^^^^^^^
  File "/home/airflow/.local/lib/python3.12/site-packages/airflow/utils/cli.py", line 115, in wrapper
    return f(*args, **kwargs)
           ^^^^^^^^^^^^^^^^^^
  File "/home/airflow/.local/lib/python3.12/site-packages/airflow/cli/commands/task_command.py", line 483, in task_run
    task_return_code = _run_task_by_selected_method(args, _dag, ti)
                       ^^^^^^^^^^^^^^^^^^^^^^^^^^^^^^^^^^^^^^^^^^^^
  File "/home/airflow/.local/lib/python3.12/site-packages/airflow/cli/commands/task_command.py", line 256, in _run_task_by_selected_method
    return _run_raw_task(args, ti)
           ^^^^^^^^^^^^^^^^^^^^^^^
  File "/home/airflow/.local/lib/python3.12/site-packages/airflow/cli/commands/task_command.py", line 341, in _run_raw_task
    return ti._run_raw_task(
           ^^^^^^^^^^^^^^^^^
  File "/home/airflow/.local/lib/python3.12/site-packages/airflow/utils/session.py", line 97, in wrapper
    return func(*args, session=session, **kwargs)
           ^^^^^^^^^^^^^^^^^^^^^^^^^^^^^^^^^^^^^^
  File "/home/airflow/.local/lib/python3.12/site-packages/airflow/models/taskinstance.py", line 3004, in _run_raw_task
    return _run_raw_task(
           ^^^^^^^^^^^^^^
  File "/home/airflow/.local/lib/python3.12/site-packages/airflow/models/taskinstance.py", line 273, in _run_raw_task
    TaskInstance._execute_task_with_callbacks(
  File "/home/airflow/.local/lib/python3.12/site-packages/airflow/models/taskinstance.py", line 3158, in _execute_task_with_callbacks
    result = self._execute_task(context, task_orig)
             ^^^^^^^^^^^^^^^^^^^^^^^^^^^^^^^^^^^^^^
  File "/home/airflow/.local/lib/python3.12/site-packages/airflow/models/taskinstance.py", line 3182, in _execute_task
    return _execute_task(self, context, task_orig)
           ^^^^^^^^^^^^^^^^^^^^^^^^^^^^^^^^^^^^^^^
  File "/home/airflow/.local/lib/python3.12/site-packages/airflow/models/taskinstance.py", line 767, in _execute_task
    result = _execute_callable(context=context, **execute_callable_kwargs)
             ^^^^^^^^^^^^^^^^^^^^^^^^^^^^^^^^^^^^^^^^^^^^^^^^^^^^^^^^^^^^^
  File "/home/airflow/.local/lib/python3.12/site-packages/airflow/models/taskinstance.py", line 733, in _execute_callable
    return ExecutionCallableRunner(
           ^^^^^^^^^^^^^^^^^^^^^^^^
  File "/home/airflow/.local/lib/python3.12/site-packages/airflow/utils/operator_helpers.py", line 252, in run
    return self.func(*args, **kwargs)
           ^^^^^^^^^^^^^^^^^^^^^^^^^^
  File "/home/airflow/.local/lib/python3.12/site-packages/airflow/models/baseoperator.py", line 406, in wrapper
    return func(self, *args, **kwargs)
           ^^^^^^^^^^^^^^^^^^^^^^^^^^^
  File "/home/airflow/.local/lib/python3.12/site-packages/airflow/operators/bash.py", line 249, in execute
    raise AirflowException(
airflow.exceptions.AirflowException: Bash command failed. The command returned a non-zero exit code 28.
[2024-09-23T08:38:39.968+0000] {local_task_job_runner.py:266} INFO - Task exited with return code 1
[2024-09-23T08:38:39.990+0000] {taskinstance.py:3900} INFO - 0 downstream tasks scheduled from follow-on schedule check
[2024-09-23T08:38:40.065+0000] {local_task_job_runner.py:245} INFO - ::endgroup::
